Workbook

Sheet Resumen Ejecutivo CMM
A1: FINCA LA ESPERANZA - MODELO DE GESTIÓN Y CONTROL ANUAL (12 MESES)
A2: Cuadro de Mando Integral y KPIs Consolidados Anuales | Finca de 15 ha / 55 Animales
A4: 1. PARÁMETROS BASE DE LA FINCA | F4: 2. INDICADORES CLAVE DE DESEMPEÑO (KPIs)
A5: Parámetro | B5: Valor | C5: Unidad | D5: Descripción / Meta | F5: Indicador KPI | G5: Valor Calculado | H5: Unidad / Meta | I5: Evaluación Técnica
A6: Área Total Finca (ha) | B6: 15 | C6: ha | D6: Área para pastoreo y rotación | F6: Producción Promedio / Vaca | G6: =B12/B7 -> 28 | H6: L/vaca/día (>= 25.0 L/día) | I6: Excelente rendimiento individual
A7: Vacas en Ordeño | B7: 25 | C7: cabezas | D7: Hato en producción activa | F7: Carga Animal Total | G7: =B11/B6 -> 3.6666667 | H7: UGM/ha (3.0 - 4.0 UGM/ha) | I7: Alta intensidad en 15 ha
A8: Vacas Horras / Secas | B8: 6 | C8: cabezas | D8: Periodo de descanso preparto | F8: Porcentaje Vacas en Ordeño | G8: =B7/(B7+B8) -> 0.80645161 | H8: % (>= 80.0%) | I8: Eficiencia de lactancia hato
A9: Novillas de Levante | B9: 18 | C9: cabezas | D9: Reemplazos e inventario joven | F9: Tasa de Reemplazo / Novillas | G9: =B9/B7 -> 0.72 | H9: % (>= 60.0%) | I9: Garantía de autorrenovación
A10: Terneros Lactantes | B10: 6 | C10: cabezas | D10: Crías en amamantamiento / balde | F10: Capacidad Ordeño / Puesto | G10: =B7/B14 -> 8.3333333 | H10: vacas/puesto (8 - 10 vacas) | I10: Eficiencia operativa por turno
A11: Total Inventario Bovino | B11: =SUM(B7:B10) -> 55 | C11: cabezas | D11: Carga total en predio | F11: Producción Anual Estimada | G11: =B12*365 -> 255500 | H11: litros/año (~255,000 L) | I11: Meta de volumen bruto
A12: Producción Promedio Diaria | B12: 700 | C12: litros/día | D12: Base de ordeño diario (2 turnos) | F12: Consumo Agua Esp. Ordeño | G12: 1.8 | H12: L agua/L leche (< 2.0 L/L) | I12: Sostenibilidad hídrica BPG
A13: Número de Ordeños al Día | B13: 2 | C13: ordeños | D13: Turnos AM y PM | F13: Costo Estimado Producción | G13: 1020 | H13: $/L (< $1,100 / L) | I13: Margen operativo proyectado
A14: Puestos de Ordeño Mecánico | B14: 3 | C14: puestos | D14: Capacidad instalada
A15: Tanque de Enfriamiento | B15: 1 | C15: tanque | D15: Capacidad de almacenamiento en frío
A16: Personal Operativo (Empleados) | B16: 2 | C16: personas | D16: Mano de obra directa
A17: Precio Base Leche Cruda ($/L) | B17: 2250 | C17: $/L | D17: Precio promedio liquidación con bonificaciones
A19: 3. RESUMEN EJECUTIVO DE PRODUCCIÓN Y FINANZAS MES A MES (AÑO 1)
A20: Mes | B20: Días | C20: Vacas Ordeño | D20: Prod. Diaria (L) | E20: Total Litros/Mes | F20: Ingresos Leche ($) | G20: Costos Operación ($) | H20: Utilidad Neta ($) | I20: Costo / Litro ($)
A21: Enero | B21: 31 | C21: 25 | D21: 710 | E21: =B21*D21 -> 22010 | F21: =E21*$B$17 -> 49522500 | G21: 20450000 | H21: =F21-G21 -> 29072500 | I21: =G21/E21 -> 929.12313
A22: Febrero | B22: 28 | C22: 25 | D22: 695 | E22: =B22*D22 -> 19460 | F22: =E22*$B$17 -> 43785000 | G22: 19200000 | H22: =F22-G22 -> 24585000 | I22: =G22/E22 -> 986.63926
A23: Marzo | B23: 31 | C23: 24 | D23: 680 | E23: =B23*D23 -> 21080 | F23: =E23*$B$17 -> 47430000 | G23: 20100000 | H23: =F23-G23 -> 27330000 | I23: =G23/E23 -> 953.51044
A24: Abril | B24: 30 | C24: 24 | D24: 705 | E24: =B24*D24 -> 21150 | F24: =E24*$B$17 -> 47587500 | G24: 20300000 | H24: =F24-G24 -> 27287500 | I24: =G24/E24 -> 959.81087
A25: Mayo | B25: 31 | C25: 25 | D25: 725 | E25: =B25*D25 -> 22475 | F25: =E25*$B$17 -> 50568750 | G25: 20900000 | H25: =F25-G25 -> 29668750 | I25: =G25/E25 -> 929.92214
A26: Junio | B26: 30 | C26: 26 | D26: 730 | E26: =B26*D26 -> 21900 | F26: =E26*$B$17 -> 49275000 | G26: 20700000 | H26: =F26-G26 -> 28575000 | I26: =G26/E26 -> 945.20548
A27: Julio | B27: 31 | C27: 26 | D27: 715 | E27: =B27*D27 -> 22165 | F27: =E27*$B$17 -> 49871250 | G27: 20850000 | H27: =F27-G27 -> 29021250 | I27: =G27/E27 -> 940.67223
A28: Agosto | B28: 31 | C28: 25 | D28: 690 | E28: =B28*D28 -> 21390 | F28: =E28*$B$17 -> 48127500 | G28: 20400000 | H28: =F28-G28 -> 27727500 | I28: =G28/E28 -> 953.71669
A29: Septiembre | B29: 30 | C29: 25 | D29: 700 | E29: =B29*D29 -> 21000 | F29: =E29*$B$17 -> 47250000 | G29: 20250000 | H29: =F29-G29 -> 27000000 | I29: =G29/E29 -> 964.28571
A30: Octubre | B30: 31 | C30: 25 | D30: 720 | E30: =B30*D30 -> 22320 | F30: =E30*$B$17 -> 50220000 | G30: 20800000 | H30: =F30-G30 -> 29420000 | I30: =G30/E30 -> 931.89964
A31: Noviembre | B31: 30 | C31: 25 | D31: 715 | E31: =B31*D31 -> 21450 | F31: =E31*$B$17 -> 48262500 | G31: 20500000 | H31: =F31-G31 -> 27762500 | I31: =G31/E31 -> 955.71096
A32: Diciembre | B32: 31 | C32: 25 | D32: 710 | E32: =B32*D32 -> 22010 | F32: =E32*$B$17 -> 49522500 | G32: 20950000 | H32: =F32-G32 -> 28572500 | I32: =G32/E32 -> 951.84007
A33: TOTAL ANUAL | B33: =SUM(B21:B32) -> 365 | C33: =AVERAGE(C21:C32) -> 25 | D33: =AVERAGE(D21:D32) -> 707.91667 | E33: =SUM(E21:E32) -> 258410 | F33: =SUM(F21:F32) -> 581422500 | G33: =SUM(G21:G32) -> 245400000 | H33: =SUM(H21:H32) -> 336022500 | I33: =G33/E33 -> 949.65365

Sheet Inventario y Trazabilidad
A1: INVENTARIO INDIVIDUAL DE BOVINOS Y REGISTRO DE TRAZABILIDAD (55 ANIMALES)
A2: Conforme a la Ley 1659 de Trazabilidad y Normatividad Sanitaria ICA | Finca La Esperanza
A4: N° Chapeta / ID | B4: Nombre / Registro | C4: Raza / Mestizaje | D4: Categoría | E4: Lote Pastoreo | F4: Edad (Meses) | G4: Estado Reproductivo | H4: N° Partos | I4: Días en Leche | J4: Padre | K4: Madre | L4: Observaciones BPG | M4: Foto
A5: COL-2024-101 | B5: Clavelina 1 | C5: Jersey x Holstein | D5: Vaca Ordeño | E5: Lote 1 (Alta) | F5: 38 | G5: Abierta | H5: 2 | I5: 68 | J5: Toro Jersey 502 | K5: Vaca Madre 11 | L5: Apta ordeño / Sana | M5: col-2024-101.jpg
A6: COL-2024-102 | B6: Mariposa 2 | C6: Jersey x Holstein | D6: Vaca Ordeño | E6: Lote 1 (Alta) | F6: 40 | G6: Gestante | H6: 3 | I6: 76 | J6: Toro Jersey 502 | K6: Vaca Madre 12 | L6: Apta ordeño / Sana | M6: col-2024-102.jpg
A7: COL-2024-103 | B7: Clavelina 3 | C7: Jersey x Holstein | D7: Vaca Ordeño | E7: Lote 1 (Alta) | F7: 42 | G7: Abierta | H7: 4 | I7: 84 | J7: Toro Jersey 502 | K7: Vaca Madre 13 | L7: Apta ordeño / Sana | M7: col-2024-103.jpg
A8: COL-2024-104 | B8: Mariposa 4 | C8: Jersey x Holstein | D8: Vaca Ordeño | E8: Lote 1 (Alta) | F8: 44 | G8: Gestante | H8: 1 | I8: 92 | J8: Toro Jersey 502 | K8: Vaca Madre 14 | L8: Apta ordeño / Sana | M8: col-2024-104.jpg
A9: COL-2024-105 | B9: Clavelina 5 | C9: Jersey x Holstein | D9: Vaca Ordeño | E9: Lote 1 (Alta) | F9: 46 | G9: Abierta | H9: 2 | I9: 100 | J9: Toro Jersey 502 | K9: Vaca Madre 15 | L9: Apta ordeño / Sana | M9: col-2024-105.jpg
A10: COL-2024-106 | B10: Mariposa 6 | C10: Jersey x Holstein | D10: Vaca Ordeño | E10: Lote 1 (Alta) | F10: 48 | G10: Gestante | H10: 3 | I10: 108 | J10: Toro Jersey 502 | K10: Vaca Madre 16 | L10: Apta ordeño / Sana | M10: col-2024-106.jpg
A11: COL-2024-107 | B11: Clavelina 7 | C11: Jersey x Holstein | D11: Vaca Ordeño | E11: Lote 1 (Alta) | F11: 50 | G11: Abierta | H11: 4 | I11: 116 | J11: Toro Jersey 502 | K11: Vaca Madre 17 | L11: Apta ordeño / Sana | M11: col-2024-107.jpg
A12: COL-2024-108 | B12: Mariposa 8 | C12: Jersey x Holstein | D12: Vaca Ordeño | E12: Lote 1 (Alta) | F12: 52 | G12: Gestante | H12: 1 | I12: 124 | J12: Toro Jersey 502 | K12: Vaca Madre 18 | L12: Apta ordeño / Sana | M12: col-2024-108.jpg
A13: COL-2024-109 | B13: Clavelina 9 | C13: Jersey x Holstein | D13: Vaca Ordeño | E13: Lote 1 (Alta) | F13: 54 | G13: Abierta | H13: 2 | I13: 132 | J13: Toro Jersey 502 | K13: Vaca Madre 19 | L13: Apta ordeño / Sana | M13: col-2024-109.jpg
A14: COL-2024-110 | B14: Mariposa 10 | C14: Jersey x Holstein | D14: Vaca Ordeño | E14: Lote 1 (Alta) | F14: 56 | G14: Gestante | H14: 3 | I14: 140 | J14: Toro Jersey 502 | K14: Vaca Madre 20 | L14: Apta ordeño / Sana | M14: col-2024-110.jpg
A15: COL-2024-111 | B15: Clavelina 11 | C15: Jersey x Holstein | D15: Vaca Ordeño | E15: Lote 1 (Alta) | F15: 58 | G15: Abierta | H15: 4 | I15: 148 | J15: Toro Jersey 502 | K15: Vaca Madre 21 | L15: Apta ordeño / Sana | M15: col-2024-111.jpg
A16: COL-2024-112 | B16: Mariposa 12 | C16: Jersey x Holstein | D16: Vaca Ordeño | E16: Lote 1 (Alta) | F16: 36 | G16: Gestante | H16: 1 | I16: 156 | J16: Toro Jersey 502 | K16: Vaca Madre 22 | L16: Apta ordeño / Sana | M16: col-2024-112.jpg
... A59: COL-2026-406 | B59: Ternero 6 | C59: Jersey Pure | D59: Ternero Lactante | E59: Lote Cuna | F59: 8 | G59: No aplica | H59: 0 | I59: 0 | J59: Toro Jersey 502 | K59: Vaca Ordeño 6 | L59: Consumo calostro ok / Desparasitado | M59: col-2026-406.jpg

Sheet Control Lechero y Mastitis
A1: REGISTRO MENSUAL DE CONTROL LECHERO Y PRUEBA CMT (12 MESES)
A2: Monitoreo Individual de Producción y Diagnóstico de Mastitis Subclínica | Manual Asojersey
A4: 1. REGISTRO DE PRODUCCIÓN DIARIA INDIVIDUAL POR VACA EN ORDEÑO (MUESTRA MENSUAL EN KG/LITEROS)
A5: N° Chapeta | B5: Nombre Vaca | C5: Ene | D5: Feb | E5: Mar | F5: Abr | G5: May | H5: Jun | I5: Jul | J5: Ago | K5: Sep | L5: Oct | M5: Nov | N5: Dic | O5: Prom/Vaca
A6: COL-2024-101 | B6: Vaca Ordeño 1 | C6: 24.4 | D6: 25.2 | E6: 26 | F6: 24.4 | G6: 25.2 | H6: 26 | I6: 24.4 | J6: 25.2 | K6: 26 | L6: 24.4 | M6: 25.2 | N6: 26 | O6: =AVERAGE(C6:N6) -> 25.2
A7: COL-2024-102 | B7: Vaca Ordeño 2 | C7: 25.6 | D7: 26.4 | E7: 27.2 | F7: 25.6 | G7: 26.4 | H7: 27.2 | I7: 25.6 | J7: 26.4 | K7: 27.2 | L7: 25.6 | M7: 26.4 | N7: 27.2 | O7: =AVERAGE(C7:N7) -> 26.4
A8: COL-2024-103 | B8: Vaca Ordeño 3 | C8: 26.8 | D8: 27.6 | E8: 28.4 | F8: 26.8 | G8: 27.6 | H8: 28.4 | I8: 26.8 | J8: 27.6 | K8: 28.4 | L8: 26.8 | M8: 27.6 | N8: 28.4 | O8: =AVERAGE(C8:N8) -> 27.6
A9: COL-2024-104 | B9: Vaca Ordeño 4 | C9: 28 | D9: 28.8 | E9: 29.6 | F9: 28 | G9: 28.8 | H9: 29.6 | I9: 28 | J9: 28.8 | K9: 29.6 | L9: 28 | M9: 28.8 | N9: 29.6 | O9: =AVERAGE(C9:N9) -> 28.8
A10: COL-2024-105 | B10: Vaca Ordeño 5 | C10: 29.2 | D10: 30 | E10: 30.8 | F10: 29.2 | G10: 30 | H10: 30.8 | I10: 29.2 | J10: 30 | K10: 30.8 | L10: 29.2 | M10: 30 | N10: 30.8 | O10: =AVERAGE(C10:N10) -> 30
A11: COL-2024-106 | B11: Vaca Ordeño 6 | C11: 30.4 | D11: 31.2 | E11: 32 | F11: 30.4 | G11: 31.2 | H11: 32 | I11: 30.4 | J11: 31.2 | K11: 32 | L11: 30.4 | M11: 31.2 | N11: 32 | O11: =AVERAGE(C11:N11) -> 31.2
A12: COL-2024-107 | B12: Vaca Ordeño 7 | C12: 23.2 | D12: 24 | E12: 24.8 | F12: 23.2 | G12: 24 | H12: 24.8 | I12: 23.2 | J12: 24 | K12: 24.8 | L12: 23.2 | M12: 24 | N12: 24.8 | O12: =AVERAGE(C12:N12) -> 24
A13: COL-2024-108 | B13: Vaca Ordeño 8 | C13: 24.4 | D13: 25.2 | E13: 26 | F13: 24.4 | G13: 25.2 | H13: 26 | I13: 24.4 | J13: 25.2 | K13: 26 | L13: 24.4 | M13: 25.2 | N13: 26 | O13: =AVERAGE(C13:N13) -> 25.2
A14: COL-2024-109 | B14: Vaca Ordeño 9 | C14: 25.6 | D14: 26.4 | E14: 27.2 | F14: 25.6 | G14: 26.4 | H14: 27.2 | I14: 25.6 | J14: 26.4 | K14: 27.2 | L14: 25.6 | M14: 26.4 | N14: 27.2 | O14: =AVERAGE(C14:N14) -> 26.4
A15: COL-2024-110 | B15: Vaca Ordeño 10 | C15: 26.8 | D15: 27.6 | E15: 28.4 | F15: 26.8 | G15: 27.6 | H15: 28.4 | I15: 26.8 | J15: 27.6 | K15: 28.4 | L15: 26.8 | M15: 27.6 | N15: 28.4 | O15: =AVERAGE(C15:N15) -> 27.6
A16: COL-2024-111 | B16: Vaca Ordeño 11 | C16: 28 | D16: 28.8 | E16: 29.6 | F16: 28 | G16: 28.8 | H16: 29.6 | I16: 28 | J16: 28.8 | K16: 29.6 | L16: 28 | M16: 28.8 | N16: 29.6 | O16: =AVERAGE(C16:N16) -> 28.8
A17: COL-2024-112 | B17: Vaca Ordeño 12 | C17: 29.2 | D17: 30 | E17: 30.8 | F17: 29.2 | G17: 30 | H17: 30.8 | I17: 29.2 | J17: 30 | K17: 30.8 | L17: 29.2 | M17: 30 | N17: 30.8 | O17: =AVERAGE(C17:N17) -> 30
... A30: COL-2024-125 | B30: Vaca Ordeño 25 | C30: 28 | D30: 28.8 | E30: 29.6 | F30: 28 | G30: 28.8 | H30: 29.6 | I30: 28 | J30: 28.8 | K30: 29.6 | L30: 28 | M30: 28.8 | N30: 29.6 | O30: =AVERAGE(C30:N30) -> 28.8
A31: PROMEDIO HATO | B31: 25 Vacas | C31: =AVERAGE(C6:C30) -> 26.704 | D31: =AVERAGE(D6:D30) -> 27.504 | E31: =AVERAGE(E6:E30) -> 28.304 | F31: =AVERAGE(F6:F30) -> 26.704 | G31: =AVERAGE(G6:G30) -> 27.504 | H31: =AVERAGE(H6:H30) -> 28.304 | I31: =AVERAGE(I6:I30) -> 26.704 | J31: =AVERAGE(J6:J30) -> 27.504 | ... O31: =AVERAGE(O6:O30) -> 27.504
A33: 2. MONITOREO DE MASTITIS SUBCLÍNICA (TEST DE CALIFORNIA - CMT MENSUAL)
A34: N° Chapeta | B34: Cuarto AI | C34: Cuarto AD | D34: Cuarto PI | E34: Cuarto PD | F34: Resultado CMT | G34: Acción Correctiva BPG
A35: COL-2024-101 | B35: Negativo | C35: Negativo | D35: Negativo | E35: Negativo | F35: Sano | G35: Rutina normal de sellado
A36: COL-2024-102 | B36: Traza | C36: Negativo | D36: Negativo | E36: Negativo | F36: Atención | G36: Monitoreo en próximo ordeño
A37: COL-2024-103 | B37: Negativo | C37: Grado 1 (+) | D37: Negativo | E37: Negativo | F37: Subclínica | G37: Desinfección intensiva / Sellador reactivo
A38: COL-2024-104 | B38: Negativo | C38: Negativo | D38: Negativo | E38: Negativo | F38: Sano | G38: Rutina normal de sellado
A39: COL-2024-105 | B39: Grado 2 (++) | C39: Negativo | D39: Negativo | E39: Traza | F39: Alerta Clin. | G39: Aislamiento de leche / Pauta veterinaria
A41: 3. PRODUCCIÓN POR ORDEÑO AM vs PM (L/VACA/DÍA · PROMEDIO MENSUAL) — DATOS SIMULADOS
A42: N° Chapeta | B42: Nombre Vaca | C42: Ordeño AM (L) | D42: Ordeño PM (L) | E42: Total día (L) | F42: % AM del total | G42: Diferencia AM – PM (L)
A43: COL-2024-101 | B43: Vaca Ordeño 1 | C43: 14.3 | D43: 10.9 | E43: =C43+D43 -> 25.2 | F43: =C43/E43 -> 0.56746032 | G43: =C43-D43 -> 3.4
A44: COL-2024-102 | B44: Vaca Ordeño 2 | C44: 14.1 | D44: 12.3 | E44: =C44+D44 -> 26.4 | F44: =C44/E44 -> 0.53409091 | G44: =C44-D44 -> 1.8
A45: COL-2024-103 | B45: Vaca Ordeño 3 | C45: 15.6 | D45: 12 | E45: =C45+D45 -> 27.6 | F45: =C45/E45 -> 0.56521739 | G45: =C45-D45 -> 3.6
A46: COL-2024-104 | B46: Vaca Ordeño 4 | C46: 15.1 | D46: 13.7 | E46: =C46+D46 -> 28.8 | F46: =C46/E46 -> 0.52430556 | G46: =C46-D46 -> 1.4
A47: COL-2024-105 | B47: Vaca Ordeño 5 | C47: 18.8 | D47: 11.2 | E47: =C47+D47 -> 30 | F47: =C47/E47 -> 0.62666667 | G47: =C47-D47 -> 7.6
A48: COL-2024-106 | B48: Vaca Ordeño 6 | C48: 16.5 | D48: 14.7 | E48: =C48+D48 -> 31.2 | F48: =C48/E48 -> 0.52884615 | G48: =C48-D48 -> 1.8
A49: COL-2024-107 | B49: Vaca Ordeño 7 | C49: 13.6 | D49: 10.4 | E49: =C49+D49 -> 24 | F49: =C49/E49 -> 0.56666667 | G49: =C49-D49 -> 3.2
A50: COL-2024-108 | B50: Vaca Ordeño 8 | C50: 13.2 | D50: 12 | E50: =C50+D50 -> 25.2 | F50: =C50/E50 -> 0.52380952 | G50: =C50-D50 -> 1.2
A51: COL-2024-109 | B51: Vaca Ordeño 9 | C51: 14.8 | D51: 11.6 | E51: =C51+D51 -> 26.4 | F51: =C51/E51 -> 0.56060606 | G51: =C51-D51 -> 3.2
A52: COL-2024-110 | B52: Vaca Ordeño 10 | C52: 14.4 | D52: 13.2 | E52: =C52+D52 -> 27.6 | F52: =C52/E52 -> 0.52173913 | G52: =C52-D52 -> 1.2
A53: COL-2024-111 | B53: Vaca Ordeño 11 | C53: 15.1 | D53: 13.7 | E53: =C53+D53 -> 28.8 | F53: =C53/E53 -> 0.52430556 | G53: =C53-D53 -> 1.4
A54: COL-2024-112 | B54: Vaca Ordeño 12 | C54: 16.8 | D54: 13.2 | E54: =C54+D54 -> 30 | F54: =C54/E54 -> 0.56 | G54: =C54-D54 -> 3.6
... A67: COL-2024-125 | B67: Vaca Ordeño 25 | C67: 16.3 | D67: 12.5 | E67: =C67+D67 -> 28.8 | F67: =C67/E67 -> 0.56597222 | G67: =C67-D67 -> 3.8
...

Sheet Reproducción y Sanidad
A1: REGISTRO DE REPRODUCCIÓN Y PLAN SANITARIO OFICIAL ICA (12 MESES)
A2: Control de Días Abiertos, Inseminación y Calendario de Vacunación | Finca La Esperanza
A4: 1. REGISTRO REPRODUCTIVO Y CONTROL DE DÍAS ABIERTOS (META: <= 85 DÍAS)
A5: N° Chapeta | B5: Fecha Último Parto | C5: N° Partos | D5: Fecha Servicio/IA | E5: Toro / Pajilla | F5: Diagnóstico Preñez | G5: Fecha Probable Parto | H5: Días Abiertos | I5: Estado Reproductivo
A6: COL-2024-101 | B6: 2025-11-10 | C6: 2 | D6: 2026-01-25 | E6: Jersey 502 | F6: Confirmado (Eco) | G6: 2026-11-03 | H6: 76 | I6: Gestante
A7: COL-2024-102 | B7: 2025-12-05 | C7: 3 | D7: 2026-02-18 | E7: Jersey 504 | F7: Confirmado (Palp) | G7: 2026-11-26 | H7: 75 | I7: Gestante
A8: COL-2024-103 | B8: 2026-01-15 | C8: 1 | D8: 2026-04-10 | E8: Holstein 101 | F8: Pendiente | G8: 2027-01-16 | H8: 85 | I8: Servida
A9: COL-2024-104 | B9: 2026-02-01 | C9: 4 | D9: 2026-03-22 | E9: Jersey 502 | F9: Confirmado (Eco) | G9: 2026-12-28 | H9: 49 | I9: Gestante
A10: COL-2024-105 | B10: 2026-03-10 | C10: 2 | D10: Sin servicio | E10: N/A | F10: Vacía | G10: N/A | H10: 120 | I10: En Celo / Abierta
A13: 2. PLAN SANITARIO Y REGISTRO DE MEDICAMENTOS VETERINARIOS (BPG / ICA)
A14: Fecha | B14: Lote / Chapeta | C14: Diagnóstico / Evento | D14: Medicamento / Vacuna | E14: Reg. ICA | F14: Dosis / Vía | G14: Tiempo Retiro Leche (Días) | H14: Responsable | I14: Cumplimiento
A15: 2026-05-12 | B15: Todo el hato (55) | C15: Ciclo Vacunación Fiebre Aftosa | D15: Aftosa Bivalente | E15: ICA-1234 | F15: 2 ml / SC | G15: 0 | H15: Dr. Vet. Ramírez | I15: Verificado ICA
A16: 2026-05-12 | B16: Novillas (18) | C16: Vacunación Brucelosis | D16: Cepa 19 | E16: ICA-5678 | F16: 2 ml / SC | G16: 0 | H16: Dr. Vet. Ramírez | I16: Verificado ICA
A17: 2026-06-01 | B17: COL-2024-105 | C17: Tratamiento Mastitis Clínica | D17: Cefalexina Intramamaria | E17: ICA-9012 | F17: 1 jeringa / Cto | G17: 4 | H17: Empleado 1 | I17: Leche descartada 4 días
A18: 2026-07-15 | B18: Hato Adulto (31) | C18: Vermifugación Externa / Interna | D18: Ivermectina 1% | E18: ICA-3456 | F18: 1 ml / 50 kg | G18: 28 | H18: Empleado 2 | I18: Cumplido retiro

Sheet Saneamiento y Agua
A1: REGISTRO DE USO DE AGUA Y RUTINA DE DESINFECCIÓN DE EQUIPOS (BPG)
A2: Conforme a Normatividad Corantioquia y Decreto 616 de Inocuidad de la Leche | Finca La Esperanza
A4: 1. REGISTRO MENSUAL DE CONSUMO HÍDRICO Y EFICIENCIA (M3 Y LITROS/LITRO LECHE)
A5: Mes | B5: Lectura Inicial (m³) | C5: Lectura Final (m³) | D5: Consumo Mes (m³) | E5: Consumo Agua (L) | F5: Producción Leche (L) | G5: Módulo Consumo (L agua/L leche) | H5: Evaluación Ambiental
A6: Enero | B6: 1200 | C6: 1239.6 | D6: =C6-B6 -> 39.6 | E6: =D6*1000 -> 39600 | F6: ='Resumen Ejecutivo CMM'!E21 -> 22010 | G6: =E6/F6 -> 1.7991822 | H6: Eficiente (< 2.0 L/L)
A7: Febrero | B7: 1239.6 | C7: 1274.6 | D7: =C7-B7 -> 35 | E7: =D7*1000 -> 35000 | F7: ='Resumen Ejecutivo CMM'!E22 -> 19460 | G7: =E7/F7 -> 1.7985612 | H7: Eficiente (< 2.0 L/L)
A8: Marzo | B8: 1274.6 | C8: 1312.5 | D8: =C8-B8 -> 37.9 | E8: =D8*1000 -> 37900 | F8: ='Resumen Ejecutivo CMM'!E23 -> 21080 | G8: =E8/F8 -> 1.7979127 | H8: Eficiente (< 2.0 L/L)
A9: Abril | B9: 1312.5 | C9: 1350.5 | D9: =C9-B9 -> 38 | E9: =D9*1000 -> 38000 | F9: ='Resumen Ejecutivo CMM'!E24 -> 21150 | G9: =E9/F9 -> 1.7966903 | H9: Eficiente (< 2.0 L/L)
A10: Mayo | B10: 1350.5 | C10: 1390.9 | D10: =C10-B10 -> 40.4 | E10: =D10*1000 -> 40400 | F10: ='Resumen Ejecutivo CMM'!E25 -> 22475 | G10: =E10/F10 -> 1.7975528 | H10: Eficiente (< 2.0 L/L)
A11: Junio | B11: 1390.9 | C11: 1430.3 | D11: =C11-B11 -> 39.4 | E11: =D11*1000 -> 39400 | F11: ='Resumen Ejecutivo CMM'!E26 -> 21900 | G11: =E11/F11 -> 1.7990868 | H11: Eficiente (< 2.0 L/L)
A12: Julio | B12: 1430.3 | C12: 1470.2 | D12: =C12-B12 -> 39.9 | E12: =D12*1000 -> 39900 | F12: ='Resumen Ejecutivo CMM'!E27 -> 22165 | G12: =E12/F12 -> 1.8001353 | H12: Eficiente (< 2.0 L/L)
A13: Agosto | B13: 1470.2 | C13: 1508.7 | D13: =C13-B13 -> 38.5 | E13: =D13*1000 -> 38500 | F13: ='Resumen Ejecutivo CMM'!E28 -> 21390 | G13: =E13/F13 -> 1.7999065 | H13: Eficiente (< 2.0 L/L)
A14: Septiembre | B14: 1508.7 | C14: 1546.5 | D14: =C14-B14 -> 37.8 | E14: =D14*1000 -> 37800 | F14: ='Resumen Ejecutivo CMM'!E29 -> 21000 | G14: =E14/F14 -> 1.8 | H14: Eficiente (< 2.0 L/L)
A15: Octubre | B15: 1546.5 | C15: 1586.6 | D15: =C15-B15 -> 40.1 | E15: =D15*1000 -> 40100 | F15: ='Resumen Ejecutivo CMM'!E30 -> 22320 | G15: =E15/F15 -> 1.796595 | H15: Eficiente (< 2.0 L/L)
A16: Noviembre | B16: 1586.6 | C16: 1625.2 | D16: =C16-B16 -> 38.6 | E16: =D16*1000 -> 38600 | F16: ='Resumen Ejecutivo CMM'!E31 -> 21450 | G16: =E16/F16 -> 1.7995338 | H16: Eficiente (< 2.0 L/L)
A17: Diciembre | B17: 1625.2 | C17: 1664.8 | D17: =C17-B17 -> 39.6 | E17: =D17*1000 -> 39600 | F17: ='Resumen Ejecutivo CMM'!E32 -> 22010 | G17: =E17/F17 -> 1.7991822 | H17: Eficiente (< 2.0 L/L)
A18: TOTAL ANUAL | B18: 1200 | C18: 1664.8 | D18: =SUM(D6:D17) -> 464.8 | E18: =SUM(E6:E17) -> 464800 | F18: =SUM(F6:F17) -> 258410 | G18: =E18/F18 -> 1.798692 | H18: Cumple norma ambiental

Sheet Pastos y Alimentación
A1: PLAN DE ROTACIÓN DE POTREROS Y BALANCE NUTRICIONAL EN 15 HECTÁREAS
A2: Optimización de Forrajes y Suplementación Concentrada por Etapa | Finca La Esperanza
A4: 1. PROGRAMA DE ROTACIÓN DE POTREROS (15 HA DIVIDIDAS EN 15 POTREROS DE 1.0 HA)
A5: N° Potrero | B5: Área (ha) | C5: Tipo de Pasto | D5: Días Ocupación | E5: Días Descanso | F5: Aforo Promedio (kg/m²) | G5: Oferta Forraje (kg/día)
A6: Potrero 1 | B6: 1 | C6: Kikuyo Mejorado | D6: 2 | E6: 28 | F6: 4.5 | G6: =B6*10000*F6/D6 -> 22500
A7: Potrero 2 | B7: 1 | C7: Kikuyo / Trébol | D7: 2 | E7: 28 | F7: 4.5 | G7: =B7*10000*F7/D7 -> 22500
A8: Potrero 3 | B8: 1 | C8: Kikuyo Mejorado | D8: 2 | E8: 28 | F8: 4.5 | G8: =B8*10000*F8/D8 -> 22500
A9: Potrero 4 | B9: 1 | C9: Kikuyo / Trébol | D9: 2 | E9: 28 | F9: 4.5 | G9: =B9*10000*F9/D9 -> 22500
A10: Potrero 5 | B10: 1 | C10: Kikuyo Mejorado | D10: 2 | E10: 28 | F10: 4.5 | G10: =B10*10000*F10/D10 -> 22500
A11: Potrero 6 | B11: 1 | C11: Kikuyo / Trébol | D11: 2 | E11: 28 | F11: 4.5 | G11: =B11*10000*F11/D11 -> 22500
A12: Potrero 7 | B12: 1 | C12: Kikuyo Mejorado | D12: 2 | E12: 28 | F12: 4.5 | G12: =B12*10000*F12/D12 -> 22500
A13: Potrero 8 | B13: 1 | C13: Kikuyo / Trébol | D13: 2 | E13: 28 | F13: 4.5 | G13: =B13*10000*F13/D13 -> 22500
A14: Potrero 9 | B14: 1 | C14: Kikuyo Mejorado | D14: 2 | E14: 28 | F14: 4.5 | G14: =B14*10000*F14/D14 -> 22500
A15: Potrero 10 | B15: 1 | C15: Kikuyo / Trébol | D15: 2 | E15: 28 | F15: 4.5 | G15: =B15*10000*F15/D15 -> 22500
A16: Potrero 11 | B16: 1 | C16: Kikuyo Mejorado | D16: 2 | E16: 28 | F16: 4.5 | G16: =B16*10000*F16/D16 -> 22500
A17: Potrero 12 | B17: 1 | C17: Kikuyo / Trébol | D17: 2 | E17: 28 | F17: 4.5 | G17: =B17*10000*F17/D17 -> 22500
... A20: Potrero 15 | B20: 1 | C20: Kikuyo Mejorado | D20: 2 | E20: 28 | F20: 4.5 | G20: =B20*10000*F20/D20 -> 22500

Sheet Control Financiero
A1: ESTADO DE RESULTADOS Y FLUJO DE CAJA MENSUAL DE LA FINCA (12 MESES)
A2: Evaluación de Rentabilidad, Costos de Producción y Margen Operacional | Finca La Esperanza
A4: Concepto Financiero ($ COP) | B4: Ene | C4: Feb | D4: Mar | E4: Abr | F4: May | G4: Jun | H4: Jul | I4: Ago | J4: Sep | K4: Oct | L4: Nov | M4: Dic | N4: TOTAL AÑO 1
A5: INGRESOS OPERACIONALES
A6: Venta de Leche Cruda | B6: ='Resumen Ejecutivo CMM'!F21 -> 49522500 | C6: ='Resumen Ejecutivo CMM'!F22 -> 43785000 | D6: ='Resumen Ejecutivo CMM'!F23 -> 47430000 | E6: ='Resumen Ejecutivo CMM'!F24 -> 47587500 | F6: ='Resumen Ejecutivo CMM'!F25 -> 50568750 | G6: ='Resumen Ejecutivo CMM'!F26 -> 49275000 | H6: ='Resumen Ejecutivo CMM'!F27 -> 49871250 | I6: ='Resumen Ejecutivo CMM'!F28 -> 48127500 | J6: ='Resumen Ejecutivo CMM'!F29 -> 47250000 | K6: ='Resumen Ejecutivo CMM'!F30 -> 50220000 | L6: ='Resumen Ejecutivo CMM'!F31 -> 48262500 | M6: ='Resumen Ejecutivo CMM'!F32 -> 49522500 | N6: ='Resumen Ejecutivo CMM'!F33 -> 581422500
A7: Venta de Terneros Machos / Descarte | B7: 1200000 | C7: 0 | D7: 1500000 | E7: 0 | F7: 1200000 | G7: 3500000 | H7: 0 | I7: 1200000 | J7: 0 | K7: 1500000 | L7: 0 | M7: 3500000 | N7: =SUM(B7:M7) -> 13600000
A8: TOTAL INGRESOS BRUTOS | B8: =SUM(B6:B7) -> 50722500 | C8: =SUM(C6:C7) -> 43785000 | D8: =SUM(D6:D7) -> 48930000 | E8: =SUM(E6:E7) -> 47587500 | F8: =SUM(F6:F7) -> 51768750 | G8: =SUM(G6:G7) -> 52775000 | H8: =SUM(H6:H7) -> 49871250 | I8: =SUM(I6:I7) -> 49327500 | ... N8: =SUM(N6:N7) -> 595022500
A9: COSTOS DE PRODUCCIÓN Y OPERACIÓN
A10: Alimento Concentrado (Vacas, Novillas) | B10: 10800000 | C10: 10200000 | D10: 10600000 | E10: 10700000 | F10: 11000000 | G10: 10900000 | H10: 10950000 | I10: 10750000 | J10: 10650000 | K10: 10950000 | L10: 10800000 | M10: 11000000 | N10: =SUM(B10:M10) -> 129300000
A11: Sal Mineralizada y Suplementos | B11: 850000 | C11: 850000 | D11: 850000 | E11: 850000 | F11: 900000 | G11: 900000 | H11: 900000 | I11: 850000 | J11: 850000 | K11: 900000 | L11: 850000 | M11: 900000 | N11: =SUM(B11:M11) -> 10450000
A12: Mano de Obra Directa (2 Empleados) | B12: 3200000 | C12: 3200000 | D12: 3200000 | E12: 3200000 | F12: 3200000 | G12: 3200000 | H12: 3200000 | I12: 3200000 | J12: 3200000 | K12: 3200000 | L12: 3200000 | M12: 3200000 | N12: =SUM(B12:M12) -> 38400000
A13: Energía Eléctrica y Combustibles | B13: 1350000 | C13: 1280000 | D13: 1320000 | E13: 1340000 | F13: 1380000 | G13: 1360000 | H13: 1370000 | I13: 1340000 | J13: 1330000 | K13: 1370000 | L13: 1350000 | M13: 1380000 | N13: =SUM(B13:M13) -> 16170000
A14: Sanidad, Vacunas y Medicamentos BPG | B14: 800000 | C14: 600000 | D14: 850000 | E14: 650000 | F14: 950000 | G14: 700000 | H14: 800000 | I14: 650000 | J14: 600000 | K14: 850000 | L14: 750000 | M14: 900000 | N14: =SUM(B14:M14) -> 9100000
A15: Detergentes y Saneamiento Ordeño | B15: 550000 | C15: 520000 | D15: 540000 | E15: 530000 | F15: 560000 | G15: 550000 | H15: 550000 | I15: 530000 | J15: 530000 | K15: 560000 | L15: 540000 | M15: 570000 | N15: =SUM(B15:M15) -> 6530000
A16: Mantenimiento Praderas y Fertilizantes | B16: 1200000 | C16: 1000000 | D16: 1100000 | E16: 1400000 | F16: 1200000 | G16: 1100000 | H16: 1100000 | I16: 1300000 | J16: 1200000 | K16: 1100000 | L16: 1200000 | M16: 1100000 | N16: =SUM(B16:M16) -> 14000000
A17: Mantenimiento Equipos y Repuestos | B17: 600000 | C17: 450000 | D17: 540000 | E17: 530000 | F17: 610000 | G17: 500000 | H17: 480000 | I17: 680000 | J17: 390000 | K17: 470000 | L17: 710000 | M17: 400000 | N17: =SUM(B17:M17) -> 6360000
A18: Asistencia Técnica y Veterinaria | B18: 500000 | C18: 500000 | D18: 500000 | E18: 500000 | F18: 500000 | G18: 500000 | H18: 500000 | I18: 500000 | J18: 500000 | K18: 500000 | L18: 500000 | M18: 500000 | N18: =SUM(B18:M18) -> 6000000
A19: TOTAL COSTOS OPERACIONALES | B19: =SUM(B10:B18) -> 19850000 | C19: =SUM(C10:C18) -> 18600000 | D19: =SUM(D10:D18) -> 19500000 | E19: =SUM(E10:E18) -> 19700000 | F19: =SUM(F10:F18) -> 20300000 | G19: =SUM(G10:G18) -> 19710000 | H19: =SUM(H10:H18) -> 19850000 | I19: =SUM(I10:I18) -> 19800000 | ... N19: =SUM(N10:N18) -> 236310000
A20: UTILIDAD OPERACIONAL NETA | B20: =B8-B19 -> 30872500 | C20: =C8-C19 -> 25185000 | D20: =D8-D19 -> 29430000 | E20: =E8-E19 -> 27887500 | F20: =F8-F19 -> 31468750 | G20: =G8-G19 -> 33065000 | H20: =H8-H19 -> 30021250 | I20: =I8-I19 -> 29527500 | ... N20: =N8-N19 -> 358712500
A21: COSTO DE PRODUCCIÓN POR LITRO ($/L) | B21: =B19/'Resumen Ejecutivo CMM'!E21 -> 901.86279 | C21: =C19/'Resumen Ejecutivo CMM'!E22 -> 955.80678 | D21: =D19/'Resumen Ejecutivo CMM'!E23 -> 925.04744 | E21: =E19/'Resumen Ejecutivo CMM'!E24 -> 931.44208 | F21: =F19/'Resumen Ejecutivo CMM'!E25 -> 903.22581 | G21: =G19/'Resumen Ejecutivo CMM'!E26 -> 900 | H21: =H19/'Resumen Ejecutivo CMM'!E27 -> 895.55606 | I21: =I19/'Resumen Ejecutivo CMM'!E28 -> 925.6662 | J21: =J19/'Resumen Ejecutivo CMM'!E29 -> 916.66667 | K21: =K19/'Resumen Ejecutivo CMM'!E30 -> 891.57706 | L21: =L19/'Resumen Ejecutivo CMM'!E31 -> 927.73893 | M21: =M19/'Resumen Ejecutivo CMM'!E32 -> 906.40618 | N21: =N19/'Resumen Ejecutivo CMM'!E33 -> 914.47699
